scenarios/scenario3.csv
#name: scenario 3
#descr: shallow ask

# build book, shallow ask, TOB = 10/11
N, 1, VAL, 10, 100, B, 1
N, 2, VAL, 9, 100, B, 101
N, 2, VAL, 11, 100, S, 102

# hit ask, generate reject
N, 1, VAL, 11, 100, B, 2

# increase volume to Ask TOB 10, 200
N, 2, VAL, 11, 100, S, 103
F
