scenarios/scenario5.csv
#name: scenario 5
#descr: balanced book, limit above best ask

# build book, TOB = 10/11
N, 1, IBM, 10, 100, B, 1
N, 1, IBM, 12, 100, S, 2
N, 2, IBM, 9, 100, B, 101
N, 2, IBM, 11, 100, S, 102

# limit above best ask, generate reject
N, 1, IBM, 12, 100, B, 103
F
