scenarios/scenario6.csv
#name: scenario 6
#descr: tighten spread through new limit orders

# build book, TOB = 10/11
N, 1, IBM, 10, 100, B, 1
N, 1, IBM, 16, 100, S, 2
N, 2, IBM, 9, 100, B, 101
N, 2, IBM, 15, 100, S, 102

# new bid, ask TOB = 11/14
N, 2, IBM, 11, 100, B, 103
N, 1, IBM, 14, 100, S, 3
F
